Workbook

Sheet Portada
B2: Crédito Remesa Jalisco
B6: Proyecciones Financieras 3 Años · SOFOM ENR
B8: Crédito de mejoramiento de vivienda con cobro domiciliado sobre flujo de remesas
B11: Información del proyecto
B13: Materia | D13: Modelos de Crédito
B14: Institución | D14: ITESO: Instituto Tecnológico y de Estudios Superiores de Occidente
B15: Equipo | D15: David Campos · Jose Melchor · Rolando Fortanell
B16: Horizonte | D16: 3 años
B17: Estructura legal | D17: SOFOM ENR (Entidad No Regulada)
B18: Mercado objetivo | D18: Hogares receptores de remesas en Jalisco sin historial formal de crédito
B19: Modelo operativo | D19: 100% digital/remoto
B22: Índice
B24: 1.- | C24: Portada | D24: Información general del proyecto
B25: 2.- | C25: Supuestos | D25: Inputs editables
B26: 3.- | C26: Originación | D26: Originación anual y trimestral por grupo de riesgo
B27: 4.- | C27: Cartera | D27: Evolución cartera: vigente, vencida, castigos, mezcla por etapa IFRS 9
B28: 5.- | C28: Estado de Resultados | D28: Ingresos por intereses, gasto fondeo, EPRC, gastos operativos, ISR, utilidad neta
B29: 6.- | C29: Balance | D29: Activos, pasivos y capital al cierre de cada año
B30: 7.- | C30: Flujo | D30: Flujo de efectivo: operación + inversión + financiamiento
B31: 8.- | C31: Cash Flow | D31: Flujo de efectivo: operación + inversión + financiamiento
B32: 9.- | C32: Indicadores | D32: ROE, ROA, NIM, ICAP, IMOR, IMORA, eficiencia, cobertura, payback
B33: 10.- | C33: Sensibilidad | D33: Tablas bivariadas sobre supuestos clave
B34: 11.- | C34: Validaciones | D34: Validaciones sobre el balance y consistencias internas
B37: Nomenclatura de Colores
B39: ● Azul | D39: Input editable
B40: ● Negro | D40: Fórmula que depende de inputs
B41: ● Verde | D41: Referencia a otra hoja del mismo libro
B42: ● Rojo + fondo amarillo | D42: Validación de consistencia

Sheet Supuestos
B2: SUPUESTOS DEL MODELO — todos los inputs editables están en azul
B4: A. Parámetros del producto
B5: Monto promedio del crédito (MXN) | D5: 200000 | E5: Punto medio rango $50k-$500k. >$156,445 Mejoravit Renueva (Infonavit 2025).
B6: Plazo promedio del crédito (meses) | D6: 96 | E6: 8 años = mediana antigüedad remesas padrón. SOFOM vivienda 7-10 años (Banxico RIB 2025).
B7: Plazo promedio del crédito (años) | D7: =Supuestos!$D$6/12 -> 8
B9: B. Volumen de originación
B10: Créditos originados Año 1 | D10: 500 | E10: SOFOMES de nicho en primeros 12 meses operativos (HR Ratings, 2024)
B11: Crecimiento Año 2 vs Año 1 | D11: 0.3 | E11: Expansión controlada SOFOMES vivienda (HR Ratings 2026).
B12: Crecimiento Año 3 vs Año 2 | D12: 0.3 | E12: Expansión controlada SOFOMES vivienda (HR Ratings 2026).
B13: Créditos originados Año 2 | D13: =Supuestos!$D$10*(1+Supuestos!$D$11) -> 650
B14: Créditos originados Año 3 | D14: =Supuestos!$D$13*(1+Supuestos!$D$12) -> 845
B15: Monto colocado Año 1 (MXN) | D15: =Supuestos!$D$10*Supuestos!$D$5 -> 100000000
B16: Monto colocado Año 2 (MXN) | D16: =Supuestos!$D$13*Supuestos!$D$5 -> 130000000
B17: Monto colocado Año 3 (MXN) | D17: =Supuestos!$D$14*Supuestos!$D$5 -> 169000000
B19: C. Mezcla del portafolio por bucket de riesgo
B20: % Bajo Riesgo | D20: 0.4
B21: % Riesgo Medio | D21: 0.5
B22: % Alto Riesgo | D22: 0.1
B23: Suma mezcla (debe = 100%) | D23: =Supuestos!$D$20+Supuestos!$D$21+Supuestos!$D$22 -> 1
B25: D. Tasa cobrada al cliente por bucket
B26: Tasa anual Bajo Riesgo | D26: 0.2802 | E26: Notebook construcción tasa
B27: Tasa anual Riesgo Medio | D27: 0.3769
B28: Tasa anual Alto Riesgo | D28: 0.4789
B29: Tasa promedio ponderada del portafolio | D29: =Supuestos!$D$26*Supuestos!$D$20+Supuestos!$D$27*Supuestos!$D$21+Supuestos!$D$28*Supuestos!$D$22 -> 0.34842
B31: E. Riesgo crediticio (modelo de scoring)
B32: PD anual Bajo Riesgo | D32: 0.0021 | E32: Modelo XGBoost
B33: PD anual Riesgo Medio | D33: 0.0306
B34: PD anual Alto Riesgo | D34: 0.2124
B35: PD ponderada del portafolio | D35: =Supuestos!$D$32*Supuestos!$D$20+Supuestos!$D$33*Supuestos!$D$21+Supuestos!$D$34*Supuestos!$D$22 -> 0.03738
B36: LGD del producto (severidad de pérdida) | D36: 0.45 | E36: Punto medio: hipotecario 14.5% (Moody's BBVA) vs consumo 83.9%.
B37: Pérdida esperada anual ponderada (PD × LGD) | D37: =Supuestos!$D$35*Supuestos!$D$36 -> 0.016821
B39: F. Costo de fondeo (pasivo de la SOFOM)
B40: Tasa libre de riesgo (TIIE 28) | D40: 0.069971 | E40: Banxico, 8 mayo 2026 (TIIE 28 días).
B41: Spread de fondeo SOFOM ENR sobre TIIE | D41: 0.035 | E41: TIIE para SOFOM sin historial (SHF, 2025)
B42: Costo de fondeo total (TIIE + spread) | D42: =Supuestos!$D$40+Supuestos!$D$41 -> 0.104971
B43: Apalancamiento objetivo (Pasivo / Activo) | D43: 0.85 | E43: (CNBV Basilea III, 2018)(HR Ratings, 2024).
B45: G. Capital y regulación
B46: Capital inicial (equity, MXN) | D46: 10000000 | E46: Soporta ICAP mínimo Basilea III.
B47: Capital regulatorio mínimo (Basilea III) | D47: 0.105 | E47: 10.5% sobre activos ponderados por riesgo. (CNBV 2018)
B48: Ponderación riesgo del activo | D48: 1 | E48: (CNBV 2018)
...

Sheet Originación
B2: ORIGINACIÓN — créditos colocados por año y bucket
D4: Año 1 | E4: Año 2 | F4: Año 3 | G4: Total 3Y
B5: Total créditos originados | D5: =Supuestos!$D$10 -> 500 | E5: =Supuestos!$D$13 -> 650 | F5: =Supuestos!$D$14 -> 845 | G5: =SUM(D5:F5) -> 1995
B6: Monto promedio por crédito (MXN) | D6: =Supuestos!$D$5 -> 200000 | E6: =Supuestos!$D$5 -> 200000 | F6: =Supuestos!$D$5 -> 200000
B7: Monto total colocado (MXN) | D7: =D5*D6 -> 100000000 | E7: =E5*E6 -> 130000000 | F7: =F5*F6 -> 169000000 | G7: =SUM(D7:F7) -> 399000000
B9: Originación por bucket de riesgo
D10: Año 1 | E10: Año 2 | F10: Año 3
B11: Bajo Riesgo (≥ 700) — créditos | D11: =ROUND(Supuestos!$D$10*Supuestos!$D$20,0) -> 200 | E11: =ROUND(Supuestos!$D$13*Supuestos!$D$20,0) -> 260 | F11: =ROUND(Supuestos!$D$14*Supuestos!$D$20,0) -> 338
B12: Riesgo Medio (500-700) — créditos | D12: =ROUND(Supuestos!$D$10*Supuestos!$D$21,0) -> 250 | E12: =ROUND(Supuestos!$D$13*Supuestos!$D$21,0) -> 325 | F12: =ROUND(Supuestos!$D$14*Supuestos!$D$21,0) -> 423
B13: Alto Riesgo (< 500) — créditos | D13: =ROUND(Supuestos!$D$10*Supuestos!$D$22,0) -> 50 | E13: =ROUND(Supuestos!$D$13*Supuestos!$D$22,0) -> 65 | F13: =ROUND(Supuestos!$D$14*Supuestos!$D$22,0) -> 85
B14: Total créditos | D14: =SUM(D11:D13) -> 500 | E14: =SUM(E11:E13) -> 650 | F14: =SUM(F11:F13) -> 846
B16: Monto colocado por bucket (MXN)
D17: Año 1 | E17: Año 2 | F17: Año 3
B18: Bajo Riesgo (≥ 700) — monto | D18: =Supuestos!$D$10*Supuestos!$D$20*Supuestos!$D$5 -> 40000000 | E18: =Supuestos!$D$13*Supuestos!$D$20*Supuestos!$D$5 -> 52000000 | F18: =Supuestos!$D$14*Supuestos!$D$20*Supuestos!$D$5 -> 67600000
B19: Riesgo Medio (500-700) — monto | D19: =Supuestos!$D$10*Supuestos!$D$21*Supuestos!$D$5 -> 50000000 | E19: =Supuestos!$D$13*Supuestos!$D$21*Supuestos!$D$5 -> 65000000 | F19: =Supuestos!$D$14*Supuestos!$D$21*Supuestos!$D$5 -> 84500000
B20: Alto Riesgo (< 500) — monto | D20: =Supuestos!$D$10*Supuestos!$D$22*Supuestos!$D$5 -> 10000000 | E20: =Supuestos!$D$13*Supuestos!$D$22*Supuestos!$D$5 -> 13000000 | F20: =Supuestos!$D$14*Supuestos!$D$22*Supuestos!$D$5 -> 16900000
B21: Total monto colocado | D21: =SUM(D18:D20) -> 100000000 | E21: =SUM(E18:E20) -> 130000000 | F21: =SUM(F18:F20) -> 169000000
B24: Originación trimestral (distribución uniforme con estacionalidad de remesas)
B25: Factor estacional | D25: Q1 | E25: Q2 | F25: Q3 | G25: Q4
B26: Factor de peso trimestral | D26: 0.2 | E26: 0.25 | F26: 0.25 | G26: 0.3
B27: Suma (check) | D27: =SUM(D26:G26) -> 1
B29: Año 1 — créditos trimestrales | D29: =ROUND(Supuestos!$D$10*D26,0) -> 100 | E29: =ROUND(Supuestos!$D$10*E26,0) -> 125 | F29: =ROUND(Supuestos!$D$10*F26,0) -> 125 | G29: =ROUND(Supuestos!$D$10*G26,0) -> 150
B30: Año 2 — créditos trimestrales | D30: =ROUND(Supuestos!$D$13*D26,0) -> 130 | E30: =ROUND(Supuestos!$D$13*E26,0) -> 163 | F30: =ROUND(Supuestos!$D$13*F26,0) -> 163 | G30: =ROUND(Supuestos!$D$13*G26,0) -> 195
B31: Año 3 — créditos trimestrales | D31: =ROUND(Supuestos!$D$14*D26,0) -> 169 | E31: =ROUND(Supuestos!$D$14*E26,0) -> 211 | F31: =ROUND(Supuestos!$D$14*F26,0) -> 211 | G31: =ROUND(Supuestos!$D$14*G26,0) -> 254
B34: Saldo promedio sobre el año (originaciones distribuidas, factor 0.5)
B35: Originación promedio ponderada | D35: Año 1 | E35: Año 2 | F35: Año 3
B36: Monto promedio del año (50% colocación año en curso) | D36: =Supuestos!$D$15/2 -> 50000000 | E36: =Supuestos!$D$16/2 -> 65000000 | F36: =Supuestos!$D$17/2 -> 84500000

Sheet Cartera
B2: CARTERA DE CRÉDITO — evolución anual
D4: Año 1 | E4: Año 2 | F4: Año 3
B5: Evolución del saldo de cartera bruta (roll-forward)
B6: Saldo inicial (cartera bruta) | D6: 0 | E6: =D11 -> 92000000 | F6: =E11 -> 196880000
B7: (+) Originación del año | D7: =Supuestos!$D$15 -> 100000000 | E7: =Supuestos!$D$16 -> 130000000 | F7: =Supuestos!$D$17 -> 169000000
B8: (-) Amortización de capital | D8: =-(Supuestos!$D$118)*(D6+D7*0.5) -> -4250000 | E8: =-(Supuestos!$D$118)*(E6+E7*0.5) -> -13345000 | F8: =-(Supuestos!$D$118)*(F6+F7*0.5) -> -23917300
B9: (-) Prepago voluntario | D9: =-(Supuestos!$D$119)*(D6+D7*0.5) -> -2500000 | E9: =-(Supuestos!$D$119)*(E6+E7*0.5) -> -7850000 | F9: =-(Supuestos!$D$119)*(F6+F7*0.5) -> -14069000
B10: (-) Castigos | D10: =-Supuestos!$D$115*(D6+D7*0.5) -> -1250000 | E10: =-Supuestos!$D$115*(E6+E7*0.5) -> -3925000 | F10: =-Supuestos!$D$115*(F6+F7*0.5) -> -7034500
B11: Saldo final (cartera bruta) | D11: =D6+D7+D8+D9+D10 -> 92000000 | E11: =E6+E7+E8+E9+E10 -> 196880000 | F11: =F6+F7+F8+F9+F10 -> 320859200
B13: Saldo promedio del año (intereses) | D13: =(D6+D11)/2 -> 46000000 | E13: =(E6+E11)/2 -> 144440000 | F13: =(F6+F11)/2 -> 258869600
B15: Clasificación IFRS 9 sobre saldo final (etapas)
D16: Año 1 | E16: Año 2 | F16: Año 3
B17: Cartera Etapa 1 (al corriente) | D17: =D11*Supuestos!$D$106 -> 84640000 | E17: =E11*Supuestos!$D$106 -> 181129600 | F17: =F11*Supuestos!$D$106 -> 295190464
B18: Cartera Etapa 2 (30-89 días) | D18: =D11*Supuestos!$D$107 -> 4600000 | E18: =E11*Supuestos!$D$107 -> 9844000 | F18: =F11*Supuestos!$D$107 -> 16042960
B19: Cartera Etapa 3 (≥90 días) | D19: =D11*Supuestos!$D$108 -> 2760000 | E19: =E11*Supuestos!$D$108 -> 5906400 | F19: =F11*Supuestos!$D$108 -> 9625776
B20: Total (check vs saldo final) | D20: =SUM(D17:D19) -> 92000000 | E20: =SUM(E17:E19) -> 196880000 | F20: =SUM(F17:F19) -> 320859200
B22: Cartera vigente vs vencida (criterio contable)
D23: Año 1 | E23: Año 2 | F23: Año 3
B24: Cartera vigente (Etapa 1 + Etapa 2) | D24: =D17+D18 -> 89240000 | E24: =E17+E18 -> 190973600 | F24: =F17+F18 -> 311233424
B25: Cartera vencida (Etapa 3) | D25: =D19 -> 2760000 | E25: =E19 -> 5906400 | F25: =F19 -> 9625776
B26: Total cartera bruta | D26: =D24+D25 -> 92000000 | E26: =E24+E25 -> 196880000 | F26: =F24+F25 -> 320859200
B28: Estimación preventiva para riesgos crediticios (EPRC) — IFRS 9
D29: Año 1 | E29: Año 2 | F29: Año 3
B30: Reserva Etapa 1 (PD 12m × LGD) | D30: =D17*Supuestos!$D$110 -> 1423729.4 | E30: =E17*Supuestos!$D$110 -> 3046781 | F30: =F17*Supuestos!$D$110 -> 4965398.8
B31: Reserva Etapa 2 (PE lifetime) | D31: =D18*Supuestos!$D$111 -> 920000 | E31: =E18*Supuestos!$D$111 -> 1968800 | F31: =F18*Supuestos!$D$111 -> 3208592
B32: Reserva Etapa 3 (= LGD) | D32: =D19*Supuestos!$D$112 -> 1242000 | E32: =E19*Supuestos!$D$112 -> 2657880 | F32: =F19*Supuestos!$D$112 -> 4331599.2
B33: Total reservas (saldo de balance) | D33: =SUM(D30:D32) -> 3585729.4 | E33: =SUM(E30:E32) -> 7673461 | F33: =SUM(F30:F32) -> 12505590
B35: Generación de reservas del año (gasto P&G) | D35: =D33+(-D10) -> 4835729.4 | E35: =(E33-D33)+(-E10) -> 8012731.6 | F35: =(F33-E33)+(-F10) -> 11866629
B37: Cartera neta (bruta - reservas) | D37: =D11-D33 -> 88414271 | E37: =E11-E33 -> 1.8920654e+08 | F37: =F11-F33 -> 3.0835361e+08
B38: IMOR (cartera vencida / cartera total) | D38: =D25/D11 -> 0.03 | E38: =E25/E11 -> 0.03 | F38: =F25/F11 -> 0.03
B39: IMORA (cartera vencida + castigos 12m / cartera total) | D39: =(D25-D10)/D11 -> 0.043586957 | E39: =(E25-E10)/E11 -> 0.049936002 | F39: =(F25-F10)/F11 -> 0.051923947
B40: Índice de cobertura (reservas / cartera vencida) | D40: =IFERROR(D33/D25,0) -> 1.2991773 | E40: =IFERROR(E33/E25,0) -> 1.2991773 | F40: =IFERROR(F33/F25,0) -> 1.2991773

Sheet ER
B2: ESTADO DE RESULTADOS (anualizado, MXN)
C4: Año 1 | D4: Año 2 | E4: Año 3
B5: Ingresos financieros
B6: Ingresos por intereses (Tasa pond × Saldo prom) | C6: =Supuestos!$D$29*Cartera!$D$13 -> 16027320 | D6: =Supuestos!$D$29*Cartera!$E$13 -> 50325785 | E6: =Supuestos!$D$29*Cartera!$F$13 -> 90195346
B7: Comisiones por apertura (1% monto colocado) | C7: =0.01*Originación!$D$7 -> 1000000 | D7: =0.01*Originación!$E$7 -> 1300000 | E7: =0.01*Originación!$F$7 -> 1690000
B8: Total ingresos financieros | C8: =C6+C7 -> 17027320 | D8: =D6+D7 -> 51625785 | E8: =E6+E7 -> 91885346
B10: Gastos por intereses (costo de fondeo)
B11: Pasivo financiero promedio del año | C11: =Cartera!$D$13*Supuestos!$D$43 -> 39100000 | D11: =Cartera!$E$13*Supuestos!$D$43 -> 122774000 | E11: =Cartera!$F$13*Supuestos!$D$43 -> 220039160
B12: Gasto financiero (costo fondeo × pasivo promedio) | C12: =-Supuestos!$D$42*C11 -> -4104366.1 | D12: =-Supuestos!$D$42*D11 -> -12887710 | E12: =-Supuestos!$D$42*E11 -> -23097731
B14: Margen financiero (antes de EPRC) | C14: =C8+C12 -> 12922954 | D14: =D8+D12 -> 38738075 | E14: =E8+E12 -> 68787615
B16: Estimación preventiva para riesgos crediticios (EPRC) | C16: =-Cartera!$D$35 -> -4835729.4 | D16: =-Cartera!$E$35 -> -8012731.6 | E16: =-Cartera!$F$35 -> -11866629
B17: Margen financiero después de EPRC | C17: =C14+C16 -> 8087224.5 | D17: =D14+D16 -> 30725344 | E17: =E14+E16 -> 56920986
B19: Gastos de administración y operación
B20: Sueldos, salarios y prestaciones | C20: =-Supuestos!$D$81 -> -4665600 | D20: =-Supuestos!$E$81*(1+Supuestos!$D$126) -> -5408208 | E20: =-Supuestos!$F$81*(1+Supuestos!$D$126)^2 -> -6588241.9
B21: Gastos operativos fijos (renta, plataforma, otros) | C21: =-Supuestos!$D$92 -> -972000 | D21: =-Supuestos!$D$92*(1+Supuestos!$D$126) -> -1010880 | E21: =-Supuestos!$D$92*(1+Supuestos!$D$126)^2 -> -1051315.2
B22: Costos de consulta a buró (variable por originación) | C22: =-Supuestos!$D$10*Supuestos!$D$90*Supuestos!$D$89 -> -62500 | D22: =-Supuestos!$D$13*Supuestos!$D$90*Supuestos!$D$89 -> -81250 | E22: =-Supuestos!$D$14*Supuestos!$D$90*Supuestos!$D$89 -> -105625
B23: Marketing y adquisición de clientes (CAC) | C23: =-Supuestos!$D$101 -> -1500000 | D23: =-Supuestos!$D$102 -> -1755000 | E23: =-Supuestos!$D$103 -> -1939275
B24: Total gastos de administración | C24: =SUM(C20:C23) -> -7200100 | D24: =SUM(D20:D23) -> -8255338 | E24: =SUM(E20:E23) -> -9684457.1
B26: Utilidad antes de impuestos (UAFIR) | C26: =C17+C24 -> 887124.46 | D26: =D17+D24 -> 22470006 | E26: =E17+E24 -> 47236529
B28: PTU (10% sobre utilidad gravable) | C28: =-MAX(C26,0)*Supuestos!$D$123 -> -88712.446 | D28: =-MAX(D26,0)*Supuestos!$D$123 -> -2247000.6 | E28: =-MAX(E26,0)*Supuestos!$D$123 -> -4723652.9
B29: Utilidad antes de ISR | C29: =C26+C28 -> 798412.01 | D29: =D26+D28 -> 20223005 | E29: =E26+E28 -> 42512876
B30: ISR (30%) | C30: =-MAX(C29,0)*Supuestos!$D$122 -> -239523.6 | D30: =-MAX(D29,0)*Supuestos!$D$122 -> -6066901.5 | E30: =-MAX(E29,0)*Supuestos!$D$122 -> -12753863
B32: UTILIDAD NETA | C32: =C29+C30 -> 558888.41 | D32: =D29+D30 -> 14156104 | E32: =E29+E30 -> 29759013
B34: Indicadores del periodo (referencia)
B35: Tasa activa efectiva (ingresos / saldo promedio) | C35: =C8/Cartera!$D$13 -> 0.37015913 | D35: =D8/Cartera!$E$13 -> 0.35742028 | E35: =E8/Cartera!$F$13 -> 0.35494838
B36: Margen financiero / ingresos | C36: =C14/C8 -> 0.75895407 | D36: =D14/D8 -> 0.75036293 | E36: =E14/E8 -> 0.74862444
B37: Margen neto / ingresos | C37: =C32/C8 -> 0.03282304 | D37: =D32/D8 -> 0.27420607 | E37: =E32/E8 -> 0.32387116

Sheet Balance
B2: BALANCE GENERAL (al cierre del año, MXN)
C4: Año 1 | D4: Año 2 | E4: Año 3
B5: ACTIVO
B6: Cartera de crédito neta | C6: =Cartera!$D$37 -> 88414271 | D6: =Cartera!$E$37 -> 1.8920654e+08 | E6: =Cartera!$F$37 -> 3.0835361e+08
B7: Cartera bruta | C7: =Cartera!$D$11 -> 92000000 | D7: =Cartera!$E$11 -> 196880000 | E7: =Cartera!$F$11 -> 320859200
B8: (-) Reservas preventivas | C8: =-Cartera!$D$33 -> -3585729.4 | D8: =-Cartera!$E$33 -> -7673461 | E8: =-Cartera!$F$33 -> -12505590
B9: Mobiliario y equipo (neto) | C9: 250000 | D9: =C9 -> 250000 | E9: =D9 -> 250000
B10: Disponibilidades (efectivo, plug del balance) | C10: =C24-C6-C9 -> 454622.85 | D10: =D24-D6-D9 -> 3019219.9 | E10: =E24-E6-E9 -> 19084938
B11: TOTAL ACTIVO | C11: =C6+C9+C10 -> 89118893 | D11: =D6+D9+D10 -> 1.9247576e+08 | E11: =E6+E9+E10 -> 3.2768855e+08
B13: PASIVO
B14: Líneas de fondeo (SHF/NAFIN/cebures) | C14: =Cartera!$D$11*Supuestos!$D$43 -> 78200000 | D14: =Cartera!$E$11*Supuestos!$D$43 -> 167348000 | E14: =Cartera!$F$11*Supuestos!$D$43 -> 272730320
B15: Cuentas por pagar y provisiones | C15: =-ER!$C$24*0.05 -> 360005 | D15: =-ER!$D$24*0.05 -> 412766.9 | E15: =-ER!$E$24*0.05 -> 484222.86
B16: TOTAL PASIVO | C16: =C14+C15 -> 78560005 | D16: =D14+D15 -> 1.6776077e+08 | E16: =E14+E15 -> 2.7321454e+08
B18: CAPITAL CONTABLE
B19: Capital social | C19: =Supuestos!$D$46 -> 10000000 | D19: =Supuestos!$D$46 -> 10000000 | E19: =Supuestos!$D$46 -> 10000000
B20: Resultados acumulados | C20: 0 | D20: =ER!$C$32 -> 558888.41 | E20: =ER!$C$32+ER!$D$32 -> 14714992
B21: Resultado del ejercicio | C21: =ER!$C$32 -> 558888.41 | D21: =ER!$D$32 -> 14156104 | E21: =ER!$E$32 -> 29759013
B22: TOTAL CAPITAL CONTABLE | C22: =C19+C20+C21 -> 10558888 | D22: =D19+D20+D21 -> 24714992 | E22: =E19+E20+E21 -> 54474005
B24: TOTAL PASIVO + CAPITAL | C24: =C16+C22 -> 89118893 | D24: =D16+D22 -> 1.9247576e+08 | E24: =E16+E22 -> 3.2768855e+08
B26: Check: Activo - (Pasivo + Capital) | C26: =C11-C24 -> 0 | D26: =D11-D24 -> 0 | E26: =E11-E24 -> 0

Sheet Flujo
B2: FLUJO DE EFECTIVO (método indirecto, MXN)
C4: Año 1 | D4: Año 2 | E4: Año 3
B5: Actividades de operación
B6: Utilidad neta | C6: =ER!$C$32 -> 558888.41 | D6: =ER!$D$32 -> 14156104 | E6: =ER!$E$32 -> 29759013
B7: (+/-) Variación neta en cartera de crédito (neta de reservas) | C7: =-(Cartera!$D$37-0) -> -88414271 | D7: =-(Cartera!$E$37-Cartera!$D$37) -> -1.0079227e+08 | E7: =-(Cartera!$F$37-Cartera!$E$37) -> -1.1914707e+08
B8: (+/-) Variación en cuentas por pagar y provisiones | C8: =(-ER!$C$24*0.05)-0 -> 360005 | D8: =(-ER!$D$24*0.05)-(-ER!$C$24*0.05) -> 52761.9 | E8: =(-ER!$E$24*0.05)-(-ER!$D$24*0.05) -> 71455.956
B9: (+) Depreciación implícita mobiliario | C9: =0 -> 0 | D9: =Balance!C9-Balance!D9 -> 0 | E9: =Balance!D9-Balance!E9 -> 0
B10: Flujo neto de operación | C10: =C6+C7+C8+C9 -> -87495377 | D10: =D6+D7+D8+D9 -> -86583403 | E10: =E6+E7+E8+E9 -> -89316602
B12: Actividades de inversión
B13: Inversión en mobiliario y equipo | C13: -250000 | D13: 0 | E13: 0
B14: Flujo neto de inversión | C14: =C13 -> -250000 | D14: =D13 -> 0 | E14: =E13 -> 0
B16: Actividades de financiamiento
B17: Variación en líneas de fondeo (pasivo financiero) | C17: =Balance!$C$14-0 -> 78200000 | D17: =Balance!$D$14-Balance!$C$14 -> 89148000 | E17: =Balance!$E$14-Balance!$D$14 -> 105382320
B18: Aportaciones de capital (capital inicial) | C18: =Supuestos!$D$46 -> 10000000 | D18: 0 | E18: 0
B19: Flujo neto de financiamiento | C19: =C17+C18 -> 88200000 | D19: =D17+D18 -> 89148000 | E19: =E17+E18 -> 105382320
B21: Variación neta de efectivo | C21: =C10+C14+C19 -> 454622.85 | D21: =D10+D14+D19 -> 2564597 | E21: =E10+E14+E19 -> 16065718
B23: Efectivo al inicio del año | C23: 0 | D23: =Balance!$C$10 -> 454622.85 | E23: =Balance!$D$10 -> 3019219.9
B24: Efectivo al final del año | C24: =C23+C21 -> 454622.85 | D24: =D23+D21 -> 3019219.9 | E24: =E23+E21 -> 19084938
B25: Check: Efectivo final - Disponibilidades balance | C25: =C24-Balance!$C$10 -> 0 | D25: =D24-Balance!$D$10 -> -1.4901161e-08 | E25: =E24-Balance!$E$10 -> -2.9802322e-08

Sheet Cash Flows
B2: CASH FLOWS — FCFF, FCFE y valoración del proyecto (MXN)
C5: Año 0 | D5: Año 1 | E5: Año 2 | F5: Año 3 | G5: Total / VPN
B6: 1. Flujo de Caja Libre de la Firma (FCFF) (antes de financiamiento)
B7: Utilidad de operación (UAFIR antes de impuestos) | C7: 0 | D7: =ER!$C$26 -> 887124.46 | E7: =ER!$D$26 -> 22470006 | F7: =ER!$E$26 -> 47236529
B8: (+) Gasto financiero (revertir, ya está en UAFIR) | C8: 0 | D8: =-ER!$C$12 -> 4104366.1 | E8: =-ER!$D$12 -> 12887710 | F8: =-ER!$E$12 -> 23097731
B9: EBIT (resultado de operación antes de intereses e impuestos) | C9: =C7+C8 -> 0 | D9: =D7+D8 -> 4991490.6 | E9: =E7+E8 -> 35357715 | F9: =F7+F8 -> 70334260
B10: (-) Impuestos teóricos sobre EBIT (ISR efectivo) | C10: 0 | D10: =-MAX(0,D9)*(Supuestos!$D$122+Supuestos!$D$123*(1-Supuestos!$D$122)) -> -1846851.5 | E10: =-MAX(0,E9)*(Supuestos!$D$122+Supuestos!$D$123*(1-Supuestos!$D$122)) -> -13082355 | F10: =-MAX(0,F9)*(Supuestos!$D$122+Supuestos!$D$123*(1-Supuestos!$D$122)) -> -26023676
B11: NOPAT (utilidad operativa neta después de impuestos) | C11: =C9+C10 -> 0 | D11: =D9+D10 -> 3144639.1 | E11: =E9+E10 -> 22275361 | F11: =F9+F10 -> 44310584
B12: (+) Depreciación y EPRC (gastos no efectivos) | C12: 0 | D12: =Cartera!$D$35+0 -> 4835729.4 | E12: =Cartera!$E$35+50000 -> 8062731.6 | F12: =Cartera!$F$35+40000 -> 11906629
B13: (-) Capital de trabajo | C13: 0 | D13: =-((Cartera!$D$37-0)-((-ER!$C$24*0.05)-0)) -> -88054266 | E13: =-((Cartera!$E$37-Cartera!$D$37)-((-ER!$D$24*0.05)-(-ER!$C$24*0.05))) -> -1.0073951e+08 | F13: =-((Cartera!$F$37-Cartera!$E$37)-((-ER!$E$24*0.05)-(-ER!$D$24*0.05))) -> -1.1907562e+08
B14: (-) Inversión en activo fijo (CapEx) | C14: 0 | D14: -250000 | E14: 0 | F14: 0
B15: FCFF (Free Cash Flow to Firm) | C15: =C11+C12+C13+C14 -> 0 | D15: =D11+D12+D13+D14 -> -80323897 | E15: =E11+E12+E13+E14 -> -70401414 | F15: =F11+F12+F13+F14 -> -62858402
B17: 2. Flujo de Caja Libre al Accionista (FCFE) (para los socios)
B18: FCFF (línea anterior) | C18: =C15 -> 0 | D18: =D15 -> -80323897 | E18: =E15 -> -70401414 | F18: =F15 -> -62858402
B19: (-) Intereses pagados × (1 - tasa efectiva impuestos) | C19: 0 | D19: =ER!$C$12*(1-Supuestos!$D$122-Supuestos!$D$123*(1-Supuestos!$D$122)) -> -2585750.6 | E19: =ER!$D$12*(1-Supuestos!$D$122-Supuestos!$D$123*(1-Supuestos!$D$122)) -> -8119257 | F19: =ER!$E$12*(1-Supuestos!$D$122-Supuestos!$D$123*(1-Supuestos!$D$122)) -> -14551570
B20: (+) Variación neta en pasivo financiero (deuda) | C20: 0 | D20: =Balance!$C$14-0 -> 78200000 | E20: =Balance!$D$14-Balance!$C$14 -> 89148000 | F20: =Balance!$E$14-Balance!$D$14 -> 105382320
B21: FCFE (Free Cash Flow to Equity) | C21: =C15+C19+C20 -> 0 | D21: =D15+D19+D20 -> -4709647.7 | E21: =E15+E19+E20 -> 10627329 | F21: =F15+F19+F20 -> 27972347
B23: 3. Flujo del inversionista (incluye inversión inicial y valor terminal)
B24: Aportación de capital (Año 0) | C24: =-Supuestos!$D$46 -> -10000000 | D24: 0 | E24: 0 | F24: 0
B25: FCFE operativo (línea anterior) | C25: =C21 -> 0 | D25: =D21 -> -4709647.7 | E25: =E21 -> 10627329 | F25: =F21 -> 27972347
B26: (+) Valor terminal en Año 3 (perpetuidad Gordon) | C26: 0 | D26: 0 | E26: 0 | F26: =ER!$E$32*Supuestos!$D$133 -> 0
B27: Flujo total del inversionista | C27: =C24+C25+C26 -> -10000000 | D27: =D24+D25+D26 -> -4709647.7 | E27: =E24+E25+E26 -> 10627329 | F27: =F24+F25+F26 -> 27972347
B29: 4. Descuento de flujos y valoración del proyecto
B30: Periodo (t) | C30: 0 | D30: 1 | E30: 2 | F30: 3
B31: Factor de descuento [1 / (1 + Ke)^t] | C31: =1/(1+Supuestos!$D$129)^C30 -> 1 | D31: =1/(1+Supuestos!$D$129)^D30 -> 0.74074074 | E31: =1/(1+Supuestos!$D$129)^E30 -> 0.54869684 | F31: =1/(1+Supuestos!$D$129)^F30 -> 0.40644211
B32: Valor presente del flujo del inversionista | C32: =C27*C31 -> -10000000 | D32: =D27*D31 -> -3488627.9 | E32: =E27*E31 -> 5831181.7 | F32: =F27*F31 -> 11369140 | G32: =SUM(C32:F32) -> 3711693.6
B34: 5. Indicadores de valoración del proyecto
B35: VPN del proyecto (suma de VPs) | D35: =G32 -> 3711693.6
B36: TIR del equity (Internal Rate of Return) | D36: =IRR(C27:F27) -> 0.4938701
B37: Múltiplo del capital invertido (MOIC = Σ FCFE / Aportación) | D37: =(SUM(D25:F25)+F26)/Supuestos!$D$46 -> 3.3890028
B38: Valoración por múltiplo P/E × UN Año 3 (cross-check) | D38: =ER!$E$32*Supuestos!$D$132 -> 1.4879507e+08
B39: VP del valor por múltiplo de salida (descontado a hoy) | D39: =D38/(1+Supuestos!$D$129)^3 -> 60476581

Sheet Indicadores
B2: INDICADORES FINANCIEROS Y DE RIESGO
C4: Año 1 | D4: Año 2 | E4: Año 3 | F4: Referencia / Banchmark
B5: Rentabilidad
B6: ROE (Utilidad Neta / Capital promedio) | C6: =ER!$C$32/((Supuestos!$D$46+Balance!$C$22)/2) -> 0.054369516 | D6: =ER!$D$32/((Balance!$C$22+Balance!$D$22)/2) -> 0.80263943 | E6: =ER!$E$32/((Balance!$D$22+Balance!$E$22)/2) -> 0.75159465 | F6: Objetivo: 18% — Banca múltiple MX ~15-22%
B7: ROA (Utilidad Neta / Activo promedio) | C7: =ER!$C$32/(Balance!$C$11/2) -> 0.012542535 | D7: =ER!$D$32/((Balance!$C$11+Balance!$D$11)/2) -> 0.10054242 | E7: =ER!$E$32/((Balance!$D$11+Balance!$E$11)/2) -> 0.11442159 | F7: SOFOMES MX: 0.5-4.5% (HR Ratings)
B8: NIM (Margen financiero / Cartera promedio) | C8: =(ER!$C$6+ER!$C$12)/Cartera!$D$13 -> 0.25919465 | D8: =(ER!$D$6+ER!$D$12)/Cartera!$E$13 -> 0.25919465 | E8: =(ER!$E$6+ER!$E$12)/Cartera!$F$13 -> 0.25919465 | F8: Banca MX: 5-7%, SOFOMES: 8-15%
B9: Índice de eficiencia (Gastos adm / Ingreso neto) | C9: =-ER!$C$24/ER!$C$14 -> 0.5571559 | D9: =-ER!$D$24/ER!$D$14 -> 0.21310656 | E9: =-ER!$E$24/ER!$E$14 -> 0.1407878 | F9: Banca MX <50% bueno; SOFOMES 35-46%
B11: Solvencia y capitalización
B12: ICAP (Capital / Activos ponderados por riesgo) | C12: =Balance!$C$22/(Cartera!$D$11*Supuestos!$D$48) -> 0.11477053 | D12: =Balance!$D$22/(Cartera!$E$11*Supuestos!$D$48) -> 0.12553328 | E12: =Balance!$E$22/(Cartera!$F$11*Supuestos!$D$48) -> 0.16977542 | F12: Mínimo regulatorio: 10.5% (Basilea III)
B13: Apalancamiento (Pasivo / Activo) | C13: =Balance!$C$16/Balance!$C$11 -> 0.88151908 | D13: =Balance!$D$16/Balance!$D$11 -> 0.87159426 | E13: =Balance!$E$16/Balance!$E$11 -> 0.83376287 | F13: Objetivo modelo: 85%
B15: Calidad de cartera
B16: IMOR (Cartera vencida / Cartera total) | C16: =Cartera!$D$38 -> 0.03 | D16: =Cartera!$E$38 -> 0.03 | E16: =Cartera!$F$38 -> 0.03 | F16: Vivienda CNBV 2024 ~3%; banca dev. 6.15%
B17: IMORA (incluye castigos 12m) | C17: =Cartera!$D$39 -> 0.043586957 | D17: =Cartera!$E$39 -> 0.049936002 | E17: =Cartera!$F$39 -> 0.051923947 | F17: Indicador ajustado por write-offs
B18: Índice de cobertura (Reservas / Cartera vencida) | C18: =Cartera!$D$40 -> 1.2991773 | D18: =Cartera!$E$40 -> 1.2991773 | E18: =Cartera!$F$40 -> 1.2991773 | F18: SOFOMES MX 0.8x-2.1x (HR Ratings)
B19: % Cartera castigada anual | C19: =Supuestos!$D$115 -> 0.025 | D19: =Supuestos!$D$115 -> 0.025 | E19: =Supuestos!$D$115 -> 0.025 | F19: Supuesto modelo: 2.5%
B21: Crecimiento y recuperación del capital
B22: Crecimiento de cartera bruta YoY | C22: n.a. | D22: =Cartera!$E$11/Cartera!$D$11-1 -> 1.14 | E22: =Cartera!$F$11/Cartera!$E$11-1 -> 0.62971963
B23: Utilidad neta acumulada | C23: =ER!$C$32 -> 558888.41 | D23: =ER!$C$32+ER!$D$32 -> 14714992 | E23: =ER!$C$32+ER!$D$32+ER!$E$32 -> 44474005
B24: Payback del capital inicial (años) | C24: =IF(C23>=Supuestos!$D$46,1,IF(D23>=Supuestos!$D$46,1+(Supuestos!$D$46-C23)/(D23-C23),IF(E23>=Supuestos!$D$46,2+(Supuestos!$D$46-D23)/(E23-D23),99))) -> 1.6669287 | F24: Tiempo para recuperar el capital
B26: Eficiencia y productividad
B27: Cartera bruta por empleado (productividad) | C27: =Cartera!$D$11/Supuestos!$D$70 -> 11500000 | D27: =Cartera!$E$11/Supuestos!$E$70 -> 19688000 | E27: =Cartera!$F$11/Supuestos!$F$70 -> 24681477
B28: Créditos colocados por empleado | C28: =Supuestos!$D$10/Supuestos!$D$70 -> 62.5 | D28: =Supuestos!$D$13/Supuestos!$E$70 -> 65 | E28: =Supuestos!$D$14/Supuestos!$F$70 -> 65
B29: CAC / Ingreso por intereses primer año | C29: =Supuestos!$D$98/(Supuestos!$D$29*Supuestos!$D$5) -> 0.04305149 | D29: =Supuestos!$D$99/(Supuestos!$D$29*Supuestos!$D$5) -> 0.038746341 | E29: =Supuestos!$D$100/(Supuestos!$D$29*Supuestos!$D$5) -> 0.03293439
B31: Valoración del proyecto (descuento al accionista)
B32: VPN del proyecto (FCFE descontado al Ke) | C32: ='Cash Flows'!$D$35 -> 3711693.6
B33: TIR del equity (IRR sobre flujo del inversionista) | C33: ='Cash Flows'!$D$36 -> 0.4938701
B34: Costo de capital del accionista (Ke, referencia) | C34: =Supuestos!$D$129 -> 0.35
B35: MOIC (Múltiplo del capital invertido, sin descuento) | C35: ='Cash Flows'!$D$37 -> 3.3890028 | F35: Veces que el accionista recupera su inversión

Sheet Sensibilidad
B2: ANÁLISIS DE SENSIBILIDAD
B5: Tabla 1: ROE Año 3 (%): Variando PD ponderada y LGD
B7: PD ponderada base: | D7: =Supuestos!$D$35 -> 0.03738 | F7: LGD base: | H7: =Supuestos!$D$36 -> 0.45
B9: PD pond. ↓ / LGD → | C9: 0.25 | D9: 0.35 | E9: 0.45 | F9: 0.55 | G9: 0.65
B10: 0.03 | C10: =Indicadores!$E$7 + (-(($B$10*C$9 - $D$7*$H$7)*Cartera!$F$11)*(1-Supuestos!$D$122-Supuestos!$D$123*(1-Supuestos!$D$122)))/((Balance!$D$22+Balance!$E$22)/2) -> 0.16200797 | D10: =Indicadores!$E$7 + (-(($B$10*D$9 - $D$7*$H$7)*Cartera!$F$11)*(1-Supuestos!$D$122-Supuestos!$D$123*(1-Supuestos!$D$122)))/((Balance!$D$22+Balance!$E$22)/2) -> 0.14669211 | E10: =Indicadores!$E$7 + (-(($B$10*E$9 - $D$7*$H$7)*Cartera!$F$11)*(1-Supuestos!$D$122-Supuestos!$D$123*(1-Supuestos!$D$122)))/((Balance!$D$22+Balance!$E$22)/2) -> 0.13137625 | F10: =Indicadores!$E$7 + (-(($B$10*F$9 - $D$7*$H$7)*Cartera!$F$11)*(1-Supuestos!$D$122-Supuestos!$D$123*(1-Supuestos!$D$122)))/((Balance!$D$22+Balance!$E$22)/2) -> 0.11606039 | G10: =Indicadores!$E$7 + (-(($B$10*G$9 - $D$7*$H$7)*Cartera!$F$11)*(1-Supuestos!$D$122-Supuestos!$D$123*(1-Supuestos!$D$122)))/((Balance!$D$22+Balance!$E$22)/2) -> 0.10074452
B11: 0.045 | C11: =Indicadores!$E$7 + (-(($B$11*C$9 - $D$7*$H$7)*Cartera!$F$11)*(1-Supuestos!$D$122-Supuestos!$D$123*(1-Supuestos!$D$122)))/((Balance!$D$22+Balance!$E$22)/2) -> 0.14286315 | D11: =Indicadores!$E$7 + (-(($B$11*D$9 - $D$7*$H$7)*Cartera!$F$11)*(1-Supuestos!$D$122-Supuestos!$D$123*(1-Supuestos!$D$122)))/((Balance!$D$22+Balance!$E$22)/2) -> 0.11988935 | E11: =Indicadores!$E$7 + (-(($B$11*E$9 - $D$7*$H$7)*Cartera!$F$11)*(1-Supuestos!$D$122-Supuestos!$D$123*(1-Supuestos!$D$122)))/((Balance!$D$22+Balance!$E$22)/2) -> 0.096915559 | F11: =Indicadores!$E$7 + (-(($B$11*F$9 - $D$7*$H$7)*Cartera!$F$11)*(1-Supuestos!$D$122-Supuestos!$D$123*(1-Supuestos!$D$122)))/((Balance!$D$22+Balance!$E$22)/2) -> 0.073941766 | G11: =Indicadores!$E$7 + (-(($B$11*G$9 - $D$7*$H$7)*Cartera!$F$11)*(1-Supuestos!$D$122-Supuestos!$D$123*(1-Supuestos!$D$122)))/((Balance!$D$22+Balance!$E$22)/2) -> 0.050967972
B12: 0.06 | C12: =Indicadores!$E$7 + (-(($B$12*C$9 - $D$7*$H$7)*Cartera!$F$11)*(1-Supuestos!$D$122-Supuestos!$D$123*(1-Supuestos!$D$122)))/((Balance!$D$22+Balance!$E$22)/2) -> 0.12371832 | D12: =Indicadores!$E$7 + (-(($B$12*D$9 - $D$7*$H$7)*Cartera!$F$11)*(1-Supuestos!$D$122-Supuestos!$D$123*(1-Supuestos!$D$122)))/((Balance!$D$22+Balance!$E$22)/2) -> 0.093086593 | E12: =Indicadores!$E$7 + (-(($B$12*E$9 - $D$7*$H$7)*Cartera!$F$11)*(1-Supuestos!$D$122-Supuestos!$D$123*(1-Supuestos!$D$122)))/((Balance!$D$22+Balance!$E$22)/2) -> 0.062454869 | F12: =Indicadores!$E$7 + (-(($B$12*F$9 - $D$7*$H$7)*Cartera!$F$11)*(1-Supuestos!$D$122-Supuestos!$D$123*(1-Supuestos!$D$122)))/((Balance!$D$22+Balance!$E$22)/2) -> 0.031823144 | G12: =Indicadores!$E$7 + (-(($B$12*G$9 - $D$7*$H$7)*Cartera!$F$11)*(1-Supuestos!$D$122-Supuestos!$D$123*(1-Supuestos!$D$122)))/((Balance!$D$22+Balance!$E$22)/2) -> 0.00119142
B13: 0.075 | C13: =Indicadores!$E$7 + (-(($B$13*C$9 - $D$7*$H$7)*Cartera!$F$11)*(1-Supuestos!$D$122-Supuestos!$D$123*(1-Supuestos!$D$122)))/((Balance!$D$22+Balance!$E$22)/2) -> 0.10457349 | D13: =Indicadores!$E$7 + (-(($B$13*D$9 - $D$7*$H$7)*Cartera!$F$11)*(1-Supuestos!$D$122-Supuestos!$D$123*(1-Supuestos!$D$122)))/((Balance!$D$22+Balance!$E$22)/2) -> 0.066283835 | E13: =Indicadores!$E$7 + (-(($B$13*E$9 - $D$7*$H$7)*Cartera!$F$11)*(1-Supuestos!$D$122-Supuestos!$D$123*(1-Supuestos!$D$122)))/((Balance!$D$22+Balance!$E$22)/2) -> 0.027994179 | F13: =Indicadores!$E$7 + (-(($B$13*F$9 - $D$7*$H$7)*Cartera!$F$11)*(1-Supuestos!$D$122-Supuestos!$D$123*(1-Supuestos!$D$122)))/((Balance!$D$22+Balance!$E$22)/2) -> -0.010295477 | G13: =Indicadores!$E$7 + (-(($B$13*G$9 - $D$7*$H$7)*Cartera!$F$11)*(1-Supuestos!$D$122-Supuestos!$D$123*(1-Supuestos!$D$122)))/((Balance!$D$22+Balance!$E$22)/2) -> -0.048585132
B14: 0.09 | C14: =Indicadores!$E$7 + (-(($B$14*C$9 - $D$7*$H$7)*Cartera!$F$11)*(1-Supuestos!$D$122-Supuestos!$D$123*(1-Supuestos!$D$122)))/((Balance!$D$22+Balance!$E$22)/2) -> 0.085428662 | D14: =Indicadores!$E$7 + (-(($B$14*D$9 - $D$7*$H$7)*Cartera!$F$11)*(1-Supuestos!$D$122-Supuestos!$D$123*(1-Supuestos!$D$122)))/((Balance!$D$22+Balance!$E$22)/2) -> 0.039481076 | E14: =Indicadores!$E$7 + (-(($B$14*E$9 - $D$7*$H$7)*Cartera!$F$11)*(1-Supuestos!$D$122-Supuestos!$D$123*(1-Supuestos!$D$122)))/((Balance!$D$22+Balance!$E$22)/2) -> -0.0064665112 | F14: =Indicadores!$E$7 + (-(($B$14*F$9 - $D$7*$H$7)*Cartera!$F$11)*(1-Supuestos!$D$122-Supuestos!$D$123*(1-Supuestos!$D$122)))/((Balance!$D$22+Balance!$E$22)/2) -> -0.052414098 | G14: =Indicadores!$E$7 + (-(($B$14*G$9 - $D$7*$H$7)*Cartera!$F$11)*(1-Supuestos!$D$122-Supuestos!$D$123*(1-Supuestos!$D$122)))/((Balance!$D$22+Balance!$E$22)/2) -> -0.098361685
B17: Tabla 2: Utilidad Neta Año 3: Variando volumen Y1 y spread de fondeo
B19: Volumen Y1 base: | D19: =Supuestos!$D$10 -> 500 | F19: Spread fondeo base: | H19: =Supuestos!$D$41 -> 0.035
B21: Orig Y1 ↓ / Spread → | C21: 0.02 | D21: 0.0275 | E21: 0.035 | F21: 0.0425 | G21: 0.05
B22: 300 | C22: =($B$22/Supuestos!$D$10) * ER!$E$32 - (C$21-Supuestos!$D$41) * ER!$E$11 * ($B$22/Supuestos!$D$10) * (1-Supuestos!$D$122-Supuestos!$D$123*(1-Supuestos!$D$122)) -> 19103030 | D22: =($B$22/Supuestos!$D$10) * ER!$E$32 - (D$21-Supuestos!$D$41) * ER!$E$11 * ($B$22/Supuestos!$D$10) * (1-Supuestos!$D$122-Supuestos!$D$123*(1-Supuestos!$D$122)) -> 18479219 | E22: =($B$22/Supuestos!$D$10) * ER!$E$32 - (E$21-Supuestos!$D$41) * ER!$E$11 * ($B$22/Supuestos!$D$10) * (1-Supuestos!$D$122-Supuestos!$D$123*(1-Supuestos!$D$122)) -> 17855408 | F22: =($B$22/Supuestos!$D$10) * ER!$E$32 - (F$21-Supuestos!$D$41) * ER!$E$11 * ($B$22/Supuestos!$D$10) * (1-Supuestos!$D$122-Supuestos!$D$123*(1-Supuestos!$D$122)) -> 17231597 | G22: =($B$22/Supuestos!$D$10) * ER!$E$32 - (G$21-Supuestos!$D$41) * ER!$E$11 * ($B$22/Supuestos!$D$10) * (1-Supuestos!$D$122-Supuestos!$D$123*(1-Supuestos!$D$122)) -> 16607786
B23: 400 | C23: =($B$23/Supuestos!$D$10) * ER!$E$32 - (C$21-Supuestos!$D$41) * ER!$E$11 * ($B$23/Supuestos!$D$10) * (1-Supuestos!$D$122-Supuestos!$D$123*(1-Supuestos!$D$122)) -> 25470707 | D23: =($B$23/Supuestos!$D$10) * ER!$E$32 - (D$21-Supuestos!$D$41) * ER!$E$11 * ($B$23/Supuestos!$D$10) * (1-Supuestos!$D$122-Supuestos!$D$123*(1-Supuestos!$D$122)) -> 24638959 | E23: =($B$23/Supuestos!$D$10) * ER!$E$32 - (E$21-Supuestos!$D$41) * ER!$E$11 * ($B$23/Supuestos!$D$10) * (1-Supuestos!$D$122-Supuestos!$D$123*(1-Supuestos!$D$122)) -> 23807211 | F23: =($B$23/Supuestos!$D$10) * ER!$E$32 - (F$21-Supuestos!$D$41) * ER!$E$11 * ($B$23/Supuestos!$D$10) * (1-Supuestos!$D$122-Supuestos!$D$123*(1-Supuestos!$D$122)) -> 22975463 | G23: =($B$23/Supuestos!$D$10) * ER!$E$32 - (G$21-Supuestos!$D$41) * ER!$E$11 * ($B$23/Supuestos!$D$10) * (1-Supuestos!$D$122-Supuestos!$D$123*(1-Supuestos!$D$122)) -> 22143715
B24: 500 | C24: =($B$24/Supuestos!$D$10) * ER!$E$32 - (C$21-Supuestos!$D$41) * ER!$E$11 * ($B$24/Supuestos!$D$10) * (1-Supuestos!$D$122-Supuestos!$D$123*(1-Supuestos!$D$122)) -> 31838383 | D24: =($B$24/Supuestos!$D$10) * ER!$E$32 - (D$21-Supuestos!$D$41) * ER!$E$11 * ($B$24/Supuestos!$D$10) * (1-Supuestos!$D$122-Supuestos!$D$123*(1-Supuestos!$D$122)) -> 30798698 | E24: =($B$24/Supuestos!$D$10) * ER!$E$32 - (E$21-Supuestos!$D$41) * ER!$E$11 * ($B$24/Supuestos!$D$10) * (1-Supuestos!$D$122-Supuestos!$D$123*(1-Supuestos!$D$122)) -> 29759013 | F24: =($B$24/Supuestos!$D$10) * ER!$E$32 - (F$21-Supuestos!$D$41) * ER!$E$11 * ($B$24/Supuestos!$D$10) * (1-Supuestos!$D$122-Supuestos!$D$123*(1-Supuestos!$D$122)) -> 28719328 | G24: =($B$24/Supuestos!$D$10) * ER!$E$32 - (G$21-Supuestos!$D$41) * ER!$E$11 * ($B$24/Supuestos!$D$10) * (1-Supuestos!$D$122-Supuestos!$D$123*(1-Supuestos!$D$122)) -> 27679643
B25: 600 | C25: =($B$25/Supuestos!$D$10) * ER!$E$32 - (C$21-Supuestos!$D$41) * ER!$E$11 * ($B$25/Supuestos!$D$10) * (1-Supuestos!$D$122-Supuestos!$D$123*(1-Supuestos!$D$122)) -> 38206060 | D25: =($B$25/Supuestos!$D$10) * ER!$E$32 - (D$21-Supuestos!$D$41) * ER!$E$11 * ($B$25/Supuestos!$D$10) * (1-Supuestos!$D$122-Supuestos!$D$123*(1-Supuestos!$D$122)) -> 36958438 | E25: =($B$25/Supuestos!$D$10) * ER!$E$32 - (E$21-Supuestos!$D$41) * ER!$E$11 * ($B$25/Supuestos!$D$10) * (1-Supuestos!$D$122-Supuestos!$D$123*(1-Supuestos!$D$122)) -> 35710816 | F25: =($B$25/Supuestos!$D$10) * ER!$E$32 - (F$21-Supuestos!$D$41) * ER!$E$11 * ($B$25/Supuestos!$D$10) * (1-Supuestos!$D$122-Supuestos!$D$123*(1-Supuestos!$D$122)) -> 34463194 | G25: =($B$25/Supuestos!$D$10) * ER!$E$32 - (G$21-Supuestos!$D$41) * ER!$E$11 * ($B$25/Supuestos!$D$10) * (1-Supuestos!$D$122-Supuestos!$D$123*(1-Supuestos!$D$122)) -> 33215572
B26: 700 | C26: =($B$26/Supuestos!$D$10) * ER!$E$32 - (C$21-Supuestos!$D$41) * ER!$E$11 * ($B$26/Supuestos!$D$10) * (1-Supuestos!$D$122-Supuestos!$D$123*(1-Supuestos!$D$122)) -> 44573737 | D26: =($B$26/Supuestos!$D$10) * ER!$E$32 - (D$21-Supuestos!$D$41) * ER!$E$11 * ($B$26/Supuestos!$D$10) * (1-Supuestos!$D$122-Supuestos!$D$123*(1-Supuestos!$D$122)) -> 43118178 | E26: =($B$26/Supuestos!$D$10) * ER!$E$32 - (E$21-Supuestos!$D$41) * ER!$E$11 * ($B$26/Supuestos!$D$10) * (1-Supuestos!$D$122-Supuestos!$D$123*(1-Supuestos!$D$122)) -> 41662619 | F26: =($B$26/Supuestos!$D$10) * ER!$E$32 - (F$21-Supuestos!$D$41) * ER!$E$11 * ($B$26/Supuestos!$D$10) * (1-Supuestos!$D$122-Supuestos!$D$123*(1-Supuestos!$D$122)) -> 40207060 | G26: =($B$26/Supuestos!$D$10) * ER!$E$32 - (G$21-Supuestos!$D$41) * ER!$E$11 * ($B$26/Supuestos!$D$10) * (1-Supuestos!$D$122-Supuestos!$D$123*(1-Supuestos!$D$122)) -> 38751501

Sheet Validaciones
B2: VALIDACIONES
C5: Año 1 | D5: Año 2 | E5: Año 3 | F5: Status
B6: Suma mezcla bucket (debe = 100%) | C6: =Supuestos!$D$23 -> 1 | F6: =IF(ABS(C6-1)<0.0001,"ok","x") -> ok
B7: Suma etapas IFRS 9 (debe = 100%) | C7: =Supuestos!$D$109 -> 1 | F7: =IF(ABS(C7-1)<0.0001,"ok","x") -> ok
B8: Balance cuadra (Activo - Pasivo - Capital = 0) | C8: =Balance!$C$11-Balance!$C$16-Balance!$C$22 -> 0 | D8: =Balance!$D$11-Balance!$D$16-Balance!$D$22 -> 0 | E8: =Balance!$E$11-Balance!$E$16-Balance!$E$22 -> 0 | F8: =IF(AND(ABS(C8)<1,ABS(D8)<1,ABS(E8)<1),"ok","x") -> ok
B9: Efectivo final (Flujo) = Disponibilidades (Balance) | C9: =Flujo!C24-Balance!$C$10 -> 0 | D9: =Flujo!D24-Balance!$D$10 -> -1.4901161e-08 | E9: =Flujo!E24-Balance!$E$10 -> -2.9802322e-08 | F9: =IF(AND(ABS(C9)<1,ABS(D9)<1,ABS(E9)<1),"ok","x") -> ok
B10: Total cartera por etapa = Saldo final bruto | C10: =Cartera!D17+Cartera!D18+Cartera!D19-Cartera!$D$11 -> 0 | D10: =Cartera!E17+Cartera!E18+Cartera!E19-Cartera!$E$11 -> 0 | E10: =Cartera!F17+Cartera!F18+Cartera!F19-Cartera!$F$11 -> 0 | F10: =IF(AND(ABS(C10)<1,ABS(D10)<1,ABS(E10)<1),"ok","x") -> ok
B11: Vigente + Vencida = Cartera bruta | C11: =Cartera!$D$24+Cartera!$D$25-Cartera!$D$11 -> 0 | D11: =Cartera!$E$24+Cartera!$E$25-Cartera!$E$11 -> 0 | E11: =Cartera!$F$24+Cartera!$F$25-Cartera!$F$11 -> 0 | F11: =IF(AND(ABS(C11)<1,ABS(D11)<1,ABS(E11)<1),"ok","x") -> ok
B12: ICAP ≥ 10.5% (Basilea III) | C12: =IF(Indicadores!C12>=Supuestos!$D$47,1,0) -> 1 | D12: =IF(Indicadores!D12>=Supuestos!$D$47,1,0) -> 1 | E12: =IF(Indicadores!E12>=Supuestos!$D$47,1,0) -> 1 | F12: =IF(MIN(C12,D12,E12)=1,"ok","x") -> ok
B13: Utilidad neta > 0 (rentabilidad) | C13: =IF(ER!$C$32>0,1,0) -> 1 | D13: =IF(ER!$D$32>0,1,0) -> 1 | E13: =IF(ER!$E$32>0,1,0) -> 1 | F13: =IF(MIN(C13,D13,E13)=1,"ok","x") -> ok
B14: Disponibilidades > 0 (solvencia operativa) | C14: =IF(Balance!$C$10>0,1,0) -> 1 | D14: =IF(Balance!$D$10>0,1,0) -> 1 | E14: =IF(Balance!$E$10>0,1,0) -> 1 | F14: =IF(MIN(C14,D14,E14)=1,"ok","x") -> ok
B15: Cartera Vencida (Etapa 3) % es razonable (<10%) | C15: =IF(Cartera!$D$38<0.1,1,0) -> 1 | D15: =IF(Cartera!$E$38<0.1,1,0) -> 1 | E15: =IF(Cartera!$F$38<0.1,1,0) -> 1 | F15: =IF(MIN(C15,D15,E15)=1,"ok","x") -> ok
B16: Cobertura ≥ 0.8x (sano según HR Ratings) | C16: =IF(Cartera!$D$40>=0.8,1,0) -> 1 | D16: =IF(Cartera!$E$40>=0.8,1,0) -> 1 | E16: =IF(Cartera!$F$40>=0.8,1,0) -> 1 | F16: =IF(MIN(C16,D16,E16)=1,"ok","x") -> ok
B17: VPN del proyecto > 0 (crea valor) | C17: =IF('Cash Flows'!$D$35>0,1,0) -> 1 | F17: =IF(MIN(C17)=1,"ok","x") -> ok
B18: TIR del equity > Ke (rentabilidad sobre hurdle) | C18: =IF('Cash Flows'!$D$36>Supuestos!$D$129,1,0) -> 1 | F18: =IF(MIN(C18)=1,"ok","x") -> ok
B21: Resumen general
B22: Pasados | D22: =COUNTIF(F6:F19,"ok") -> 13
B23: Fallidos | D23: =COUNTIF(F6:F19,"x") -> 0
